Workbook

Sheet AMP Dealer Profile Data
A1: DEALER_CD | B1: DEALER_NAME | C1: AMP_HIERARCHY_ID | D1: DEALER_PHONE | E1: DEALER_ADDRESS | F1: DEALER_CITY | G1: DEALER_STATE | H1: DEALER_ZIP | I1: DEALER_URL | J1: DEALER_ADDTLSERVICES | K1: DEALER_SERVICE_URL | L1: DEALER_HOURS | M1: EMAIL_REPLY_TO | N1: SERVICE_MANAGER_NAME | O1: SIGNATURE_LINE_1 | P1: SIGNATURE_LINE_2 | Q1: ENGAGE_ENROLLMENT_STATUS | R1: AMENITY_1 | S1: AMENITY_2 | T1: AMENITY_3 | U1: AMENITY_4 | V1: AMENITY_5 | W1: AMENITY_6 | X1: SALES_PHONE | Y1: FACEBOOK_URL | Z1: TWITTER_URL | AA1: YOUTUBE_URL | AB1: YELP_URL | AC1: INSTAGRAM_URL | AD1: ECOMMERCE_URL | AE1: TIRE_CENTER_URL | AF1: ADDED_DATE | AG1: UPDATED_DATE | AH1: Error_Type | AI1: Notes | AJ1: Suggested_New_URL | AK1: Suggested_URL_Confidence
A2: 09163 | B2: Headquarter Toyota | C2: 50A | D2: 305-364-9800 | E2: 5895 N.W. 167th Street | F2: Hialeah | G2: FL | H2: 33015 | I2: https://www.headquartertoyota.com | J2: Spanish Speaking;Parts Center;Toyota Collision Center;Toyota Tire Center | K2: https://www.headquartertoyota.com/schedule-appointment.html | L2: Monday 7:00 am - 8:00 pm~Tuesday 7:00 am - 8:00 pm~Wednesday 7:00 am - 8:00 pm~Thursday 7:00 am - 8:00 pm~Friday 7:00 am - 8:00 pm~Saturday 7:30 am - 5:00 pm~Sunday 8:00 am - 3:00 pm | M2: barbara.damon@headquartertoyota.com | R2: Spanish Speaking | X2: 3053649800 | Y2: https://www.facebook.com/HeadquarterToyota | Z2: https://twitter.com/hqtoyota | AA2: https://www.youtube.com/user/HeadquarterToyota/about | AB2: https://www.yelp.com/biz/headquarter-toyota-miami | AC2: https://instagram.com/headquartertoyota | AE2: https://www.settirecenters.com/?uid=B78F523B-43EA-46DD-8AB01481E700187B | AF2: 2022-04-11 | AG2: 2026-01-06 | AH2: No Issue Detected
A3: 09168 | B3: Gettel Toyota of Bradenton | C3: 50B | D3: 941-756-5511 | E3: 6323 14th Street West | F3: Bradenton | G3: FL | H3: 34207 | I3: https://www.getteltoyotaofbradenton.com | J3: Spanish Speaking;Express Maintenance;Parts Center;Toyota Collision Center;Toyota Tire Center;Pres. Customer 1st Award | K3: https://www.getteltoyotaofbradenton.com/service-center-schedule-service.html | L3: Monday 7:00 am - 6:00 pm~Tuesday 7:00 am - 6:00 pm~Wednesday 7:00 am - 6:00 pm~Thursday 7:00 am - 6:00 pm~Friday 7:00 am - 6:00 pm~Saturday 7:00 am - 4:00 pm~Sunday 8:00 am - 2:00 pm | M3: jgorrill@gettel.com | R3: Spanish Speaking | X3: 9417565511 | Y3: https://www.facebook.com/getteltoyotaofbradenton | Z3: https://twitter.com/GettelToyota | AA3: https://www.youtube.com/channel/UCODmpNz8MoCNAgDB_pCrUMA/about | AB3: https://www.yelp.com/biz/gettel-toyota-bradenton | AE3: https://www.settirecenters.com/?uid=F454BAC3-B04D-47A3-909631D3F24A4388 | AF3: 2022-04-11 | AG3: 2026-05-06 | AH3: Unreachable / Timeout | AI3: ('Connection aborted.', RemoteDisconnected('Remote end closed connection without response')) | browser fallback unavailable: Page.goto: Timeout 20000ms exceeded. Call log: - navigating to "https://w
A4: 09216 | B4: West Kendall Toyota | C4: 50A | D4: 786-573-5900 | E4: 13800 SW 137th Avenue | F4: Miami | G4: FL | H4: 33186 | I4: https://www.westkendalltoyota.com | J4: Spanish Speaking;Express Maintenance;Off-Site Service Center;Toyota Tire Center | K4: https://www.westkendalltoyota.com/service/schedule-service/ | L4: Monday 7:00 am - 8:00 pm~Tuesday 7:00 am - 8:00 pm~Wednesday 7:00 am - 8:00 pm~Thursday 7:00 am - 8:00 pm~Friday 7:00 am - 8:00 pm~Saturday 7:00 am - 6:00 pm~Sunday 8:00 am - 3:00 pm | M4: karina.mair@westkendalltoyota.com | R4: Spanish Speaking | X4: 7863452600 | Y4: https://www.facebook.com/WestKendallToyota | Z4: https://twitter.com/WKendallToyota | AA4: https://www.youtube.com/user/WestKendallToyota/about | AB4: https://www.yelp.com/biz/west-kendall-toyota-sales-miami | AC4: https://instagram.com/westkendalltoyota | AE4: https://www.settirecenters.com/?uid=7B83A0E4-9506-4E6A-A5FF727D97A1972A | AF4: 2022-04-11 | AG4: 2026-05-06 | AH4: No Issue Detected
A5: 09218 | B5: Toyota of Melbourne | C5: 50C | D5: 321-254-8888 | E5: 24 North Harbor City Blvd | F5: Melbourne | G5: FL | H5: 32935 | I5: https://www.toyotaofmelbourne.com | J5: Spanish Speaking;Express Maintenance;Parts Center;Toyota Collision Center;Toyota Tire Center | K5: https://www.toyotaofmelbourne.com/service-center-schedule-service.html | L5: Monday 7:00 am - 7:00 pm~Tuesday 7:00 am - 7:00 pm~Wednesday 7:00 am - 7:00 pm~Thursday 7:00 am - 7:00 pm~Friday 7:00 am - 7:00 pm~Saturday 7:00 am - 4:00 pm~ | M5: klopez@toyotaofmelbourne.com | R5: Spanish Speaking | X5: 3212548888 | Y5: https://www.facebook.com/ToyotaOfMelbourne | Z5: https://twitter.com/toyotamelb | AA5: https://www.youtube.com/user/ToyotaMelbourne | AB5: https://www.yelp.com/biz/toyota-of-melbourne-melbourne-2 | AC5: https://instagram.com/toyotamelbourne | AE5: https://www.settirecenters.com/?uid=3473A2D2-410D-4DFE-A64D90B19F938FBF | AF5: 2022-04-11 | AG5: 2026-07-07 | AH5: Error Page Entered | AI5: Status 403 at https://www.toyotaofmelbourne.com/service-center-schedule-service.html | AK5: None (no sitemap found; homepage links yielded no candidates)
A6: 09239 | B6: Gettel Toyota of Charlotte County | C6: 50B | D6: 941-639-1155 | E6: 1801 Tamiami Trail | F6: Punta Gorda | G6: FL | H6: 33950 | I6: https://www.getteltoyotaofcharlottecounty.com | J6: Express Maintenance;Toyota Collision Center | K6: https://www.getteltoyotaofcharlottecounty.com/schedule-service-appointment.html | L6: Monday 7:00 am - 6:00 pm~Tuesday 7:00 am - 6:00 pm~Wednesday 7:00 am - 6:00 pm~Thursday 7:00 am - 6:00 pm~Friday 7:00 am - 6:00 pm~Saturday 7:00 am - 5:00 pm~ | X6: 9416391155 | AE6: https://www.settirecenters.com/?uid=344AD954-7D72-45F6-B08CEDC17960E29F | AF6: 2022-04-11 | AG6: 2026-06-08 | AH6: Redirect Drops Query String | AI6: https://www.getteltoyotaofcharlottecounty.com/schedule-service-appointment.html -> https://www.getteltoyotaofcharlottecounty.com/service/schedule-service/ (redirect drops query strings; confirmed by appending test params: https://www.getteltoyotaofcharlottecounty.com/schedule-service-appointment.html?siteid=test&utm_source=test -> https://www.getteltoyotaofcharlottecounty.com/service/schedule-service/)
A7: 09245 | B7: Sebring Toyota | C7: 50C | D7: 863-225-8576 | E7: 404 U.S. Highway 27 North | F7: Sebring | G7: FL | H7: 33870 | I7: https://www.sebringtoyota.com | K7: https://www.sebringtoyota.com/service/index.htm | L7: Monday 7:00 am - 6:00 pm~Tuesday 7:00 am - 6:00 pm~Wednesday 7:00 am - 6:00 pm~Thursday 7:00 am - 6:00 pm~Friday 7:00 am - 6:00 pm~Saturday 8:00 am - 4:00 pm~ | X7: 8633851525 | AE7: https://www.settirecenters.com/?uid=5220820A-B629-4BE4-8D0F1C031A53DD59 | AF7: 2022-06-30 | AG7: 2026-07-07 | AH7: Redirect Drops Query String | AI7: https://www.sebringtoyota.com/service/index.htm -> https://www.sebringtoyota.com/schedule-service.htm (redirect drops query strings; confirmed by appending test params: https://www.sebringtoyota.com/service/index.htm?siteid=test&utm_source=test -> https://www.sebringtoyota.com/schedule-service.htm)
A8: 10015 | B8: Milton Martin Toyota | C8: 50H | D8: 770-535-0778 | E8: 3150 Milton Martin Toyota Way | F8: Gainesville | G8: GA | H8: 30507 | I8: https://www.miltonmartintoyota.com | J8: 24-Hour Vehicle Drop Off;Advanced Diagnostics;Advanced Tune-Up Equip.;Barista/Coffee Bar;Children's Play Area;Complimentary Beverages;Express Maintenance;Toyota Collision Center;Toyota Tire Center;Pres. Customer 1st Award | K8: https://www.miltonmartintoyota.com/service/schedule-service/ | L8: Monday 7:00 am - 6:00 pm~Tuesday 7:00 am - 6:00 pm~Wednesday 7:00 am - 6:00 pm~Thursday 7:00 am - 6:00 pm~Friday 7:00 am - 6:00 pm~Saturday 7:00 am - 5:00 pm~ | R8: 24-Hour Vehicle Drop Off | S8: Advanced Diagnostics | T8: Advanced Tune-Up Equip. | U8: Barista/Coffee Bar | V8: Children's Play Area | W8: Complimentary Beverages | X8: 7705324355 | Y8: https://www.facebook.com/MMToyota/ | Z8: https://twitter.com/mmartintoyota | AA8: https://www.youtube.com/user/miltonmartintoyota1 | AB8: https://www.yelp.com/biz/milton-martin-toyota-gainesville | AE8: https://www.settirecenters.com/?uid=44AB4EF9-E8C2-4A2D-BED81B3E09F036B4 | AF8: 2022-04-11 | AG8: 2026-06-08 | AH8: No Issue Detected
A9: 10035 | B9: North Georgia Toyota | C9: 50F | D9: 706-659-0475 | E9: 1510 East Walnut Avenue | F9: Dalton | G9: GA | H9: 30721 | I9: https://www.northgeorgiatoyota.com | J9: Express Maintenance;Toyota Collision Center;Toyota Tire Center | K9: https://www.northgeorgiatoyota.com/service/schedule-service/ | L9: Monday 7:30 am - 6:00 pm~Tuesday 7:30 am - 6:00 pm~Wednesday 7:30 am - 6:00 pm~Thursday 7:30 am - 6:00 pm~Friday 7:30 am - 6:00 pm~Saturday 8:00 am - 3:00 pm~ | X9: 7062781322 | Y9: https://www.facebook.com/northgeorgiatoyota | Z9: https://twitter.com/northgatoyota | AA9: https://www.youtube.com/user/NorthGAToyota | AB9: https://www.yelp.com/biz/north-georgia-toyota-dalton | AC9: https://www.instagram.com/northgatoyota | AE9: https://www.settirecenters.com/?uid=434DFB5E-E090-4FC2-8D42EBA03F2E5BFD | AF9: 2022-04-11 | AG9: 2026-05-06 | AH9: No Issue Detected
A10: 10040 | B10: Prince Toyota | C10: 50D | D10: 229-353-0039 | E10: 2013 U.S. Highway 82 West | F10: Tifton | G10: GA | H10: 31793 | I10: https://www.princetoyota.com | J10: Toyota Tire Center | K10: https://www.princetoyota.com/schedule-service | L10: Monday 7:30 am - 6:00 pm~Tuesday 7:30 am - 6:00 pm~Wednesday 7:30 am - 6:00 pm~Thursday 7:30 am - 6:00 pm~Friday 7:30 am - 6:00 pm~Saturday 8:00 am - 2:00 pm~ | X10: 2293864000 | Y10: https://www.facebook.com/PrinceToyotaTifton | Z10: https://twitter.com/PrinceToyotaTif | AA10: https://www.youtube.com/user/princetoyotatifton | AB10: https://www.yelp.com/biz/prince-toyota-tifton | AC10: https://instagram.com/princetoyotatifton | AE10: https://www.settirecenters.com/?uid=BC926DA3-4707-4BD1-B2F86527FFAF7265 | AF10: 2022-04-11 | AG10: 2026-06-08 | AH10: No Issue Detected
A11: 10118 | B11: Nalley Toyota of Roswell | C11: 50H | D11: 770-763-7398 | E11: 11130 Alpharetta Highway | F11: Roswell | G11: GA | H11: 30076 | I11: https://www.toyotaofroswell.com | J11: 24-Hour Vehicle Drop Off;Advanced Diagnostics;Online Scheduling;Toyota Cert. Technicians;WiFi Available;Car Wash;Express Lube;Express Maintenance;Parts Center;Toyota Collision Center;Toyota Tire Center | K11: https://www.toyotaofroswell.com/service/schedule-appointment.htm | L11: Monday 7:00 am - 7:00 pm~Tuesday 7:00 am - 7:00 pm~Wednesday 7:00 am - 7:00 pm~Thursday 7:00 am - 7:00 pm~Friday 7:00 am - 7:00 pm~Saturday 7:00 am - 5:00 pm~ | R11: 24-Hour Vehicle Drop Off | S11: Advanced Diagnostics | T11: Online Scheduling | U11: Toyota Cert. Technicians | V11: WiFi Available | X11: 7705948696 | Y11: https://www.facebook.com/NalleyToyotaScionRoswell | Z11: https://x.com/nalleytoysci | AA11: https://www.youtube.com/@NalleyToyotaofRoswell | AC11: https://www.instagram.com/nalleytoyotaroswell | AE11: https://www.settirecenters.com/?uid=7A554FCC-7600-4AF7-A51731A4F89AA670 | AF11: 2022-04-11 | AG11: 2026-06-08 | AH11: No Issue Detected
A12: 10128 | B12: Five Star Toyota of Milledgeville | C12: 50G | D12: 478-453-9451 | E12: 2816 North Columbia Street | F12: Milledgeville | G12: GA | H12: 31061 | I12: https://www.fivestartoyotaofmilledgeville.com | K12: https://www.fivestartoyotaofmilledgeville.com/schedule-service-appointment.html | L12: Monday 7:30 am - 6:00 pm~Tuesday 7:30 am - 6:00 pm~Wednesday 7:30 am - 6:00 pm~Thursday 7:30 am - 6:00 pm~Friday 7:30 am - 6:00 pm~Saturday 8:00 am - 2:00 pm~ | X12: 4784539451 | Y12: https://www.facebook.com/fivestartoyotaofmilledgeville | Z12: https://twitter.com/ToyotaScionGA | AA12: https://www.youtube.com/user/louieherrontoyota | AB12: https://www.yelp.com/biz/louie-herron-toyota-milledgeville | AE12: https://www.settirecenters.com/?uid=F9BB1EB2-EAD8-456A-A481D763E1929CEE | AF12: 2022-04-11 | AG12: 2026-06-08 | AH12: Error Page Entered | AI12: Status 404 at https://www.fivestartoyotaofmilledgeville.com/schedule-service-appointment.html | AJ12: https://www.fivestartoyotaofmilledgeville.com/vehicle-finder-service/ | AK12: High
A13: 10130 | B13: Beaver Toyota of Cumming | C13: 50H | D13: 470-533-2000 | E13: 1875 Buford Highway | F13: Cumming | G13: GA | H13: 30041 | I13: https://www.beavertoyotacumming.com | J13: 24-Hour Vehicle Drop Off;Advanced Diagnostics;Advanced Tune-Up Equip.;Barista/Coffee Bar;Children's Play Area;Complimentary Beverages;Car Wash;Express Lube;Express Maintenance;On-Site Rental Vehicles;Toyota Collision Center;Pres. Customer 1st Award | K13: https://www.beavertoyotacumming.com/service/schedule-service/ | L13: Monday 7:00 am - 6:00 pm~Tuesday 7:00 am - 6:00 pm~Wednesday 7:00 am - 6:00 pm~Thursday 7:00 am - 6:00 pm~Friday 7:00 am - 6:00 pm~Saturday 7:00 am - 5:00 pm~ | M13: btcservicebdc@beavertoyota.com | N13: Chris Calavan | O13: We're here to WOW ya! | R13: 24-Hour Vehicle Drop Off | S13: Advanced Diagnostics | T13: Advanced Tune-Up Equip. | U13: Barista/Coffee Bar | V13: Children's Play Area | W13: Complimentary Beverages | X13: 4705332000 | Y13: https://www.facebook.com/beavertoyotacumming/ | AA13: https://www.youtube.com/c/BeaverToyotaofCumming/videos | AC13: https://www.instagram.com/beavertoyotacumming/?hl=en | AE13: https://www.settirecenters.com/?uid=C1F18A82-9DB9-4A2B-ABFD2BD10983D84F | AF13: 2022-04-11 | AG13: 2026-07-07 | AH13: No Issue Detected
A14: 10131 | B14: Stone Mountain Toyota | C14: 50H | D14: 770-736-0159 | E14: 4220 Stone Mountain Highway | F14: Lilburn | G14: GA | H14: 30047 | I14: https://www.stonemountaintoyota.com | J14: Spanish Speaking | K14: https://stonemountaintoyota.com/schedule-service | L14: Monday 7:00 am - 7:00 pm~Tuesday 7:00 am - 7:00 pm~Wednesday 7:00 am - 7:00 pm~Thursday 7:00 am - 7:00 pm~Friday 7:00 am - 7:00 pm~Saturday 7:00 am - 5:00 pm~ | R14: Spanish Speaking | X14: 7707360030 | AE14: https://www.settirecenters.com/?uid=CF653515-ECBF-446E-99D9CE7298E4DD6C | AF14: 2022-04-11 | AG14: 2026-06-08 | AH14: Unreachable / Timeout | AI14: ('Connection aborted.', RemoteDisconnected('Remote end closed connection without response')) | browser fallback unavailable: Page.goto: Timeout 20000ms exceeded. Call log: - navigating to "https://s
A15: 10132 | B15: Nalley Toyota Union City | C15: 50H | D15: 770-284-8361 | E15: 4115 Jonesboro Road | F15: Union City | G15: GA | H15: 30291 | I15: https://www.toyotaofunioncity.com | K15: https://www.toyotaofunioncity.com/service/schedule-appointment.htm | L15: Monday 7:00 am - 6:00 pm~Tuesday 7:00 am - 6:00 pm~Wednesday 7:00 am - 6:00 pm~Thursday 7:00 am - 6:00 pm~Friday 7:00 am - 6:00 pm~Saturday 7:00 am - 4:00 pm~ | X15: 7709648888 | AE15: https://www.settirecenters.com/?uid=CB376CA3-E3D4-4F3B-9A9B6C2F4AB587FE | AF15: 2022-04-11 | AG15: 2026-07-07 | AH15: No Issue Detected
A16: 10138 | B16: Krause Toyota South Atlanta | C16: 50H | D16: 770-961-0225 | E16: 6865 Jonesboro Road | F16: Morrow | G16: GA | H16: 30260 | I16: https://www.krausetoyotasouthatlanta.com | L16: Monday 7:00 am - 7:00 pm~Tuesday 7:00 am - 7:00 pm~Wednesday 7:00 am - 7:00 pm~Thursday 7:00 am - 7:00 pm~Friday 7:00 am - 7:00 pm~Saturday 7:00 am - 5:00 pm~ | X16: 7709610225 | AE16: https://www.settirecenters.com/?uid=F20ED9D1-614B-46F1-8531FF416AB3877E | AF16: 2026-07-02 | AG16: 2026-07-07 | AH16: No URL | AJ16: https://www.krausetoyotasouthatlanta.com/service/toyota-maintenance-schedule/ | AK16: High
A17: 10139 | B17: Group 1 Toyota Stone Mountain | C17: 50H | D17: 770-736-0030 | E17: 4220 Stone Mountain Highway | F17: Lilburn | G17: GA | H17: 30047 | I17: https://www.group1toyotastonemountain.com | L17: Monday 7:00 am - 7:00 pm~Tuesday 7:00 am - 7:00 pm~Wednesday 7:00 am - 7:00 pm~Thursday 7:00 am - 7:00 pm~Friday 7:00 am - 7:00 pm~Saturday 7:00 am - 5:00 pm~ | X17: 7707360030 | AE17: https://www.settirecenters.com/?uid=CF653515-ECBF-446E-99D9CE7298E4DD6C | AF17: 2026-07-02 | AG17: 2026-07-07 | AH17: No URL | AJ17: https://www.group1toyotastonemountain.com/service/schedule-service/ | AK17: High
A18: 11011 | B18: Stone's Town and Country Toyota | C18: 136 | D18: 208-356-9366 | E18: 615 S. Yellowstone Highway | F18: Rexburg | G18: ID | H18: 83440 | I18: https://www.stonestoyota.com | J18: 24-Hour Vehicle Drop Off;Advanced Diagnostics;Advanced Tune-Up Equip.;Barista/Coffee Bar;Children's Play Area;Complimentary Beverages;Car Wash;Express Lube;Parts Center;Toyota Tire Center | K18: https://www.stonestoyota.com/toyota-schedule-service/ | L18: Monday 7:30 am - 6:00 pm~Tuesday 7:30 am - 6:00 pm~Wednesday 7:30 am - 6:00 pm~Thursday 7:30 am - 6:00 pm~Friday 7:30 am - 6:00 pm~Saturday 9:00 am - 5:00 pm~ | R18: 24-Hour Vehicle Drop Off | S18: Advanced Diagnostics | T18: Advanced Tune-Up Equip. | U18: Barista/Coffee Bar | V18: Children's Play Area | W18: Complimentary Beverages | X18: 2083569366 | Y18: https://www.facebook.com/stonestoyota | Z18: https://twitter.com/stonestoyota | AB18: https://www.yelp.com/biz/stones-toyota-rexburg | AE18: https://www.toyotatirecenter.com/?uid=688EB5EC-A04C-4526-ADDA64A089DBA0D5 | AF18: 2022-04-11 | AG18: 2026-06-08 | AH18: Error Page Entered | AI18: Status 403 at https://www.stonestoyota.com/toyota-schedule-service/ | AK18: None (no sitemap found; homepage links yielded no candidates)
A19: 04277 | B19: North Bakersfield Toyota | C19: 118 | D19: 661-218-1679 | E19: 19651 Industry Prkwy Dr. | F19: Bakersfield | G19: CA | H19: 93308 | I19: https://www.northbakersfieldtoyota.com | J19: 24-Hour Vehicle Drop Off;Advanced Diagnostics;Complimentary Ride Share;EV Charging Station;Late Pickup;Online Scheduling;Car Wash;On-Site Rental Vehicles;Parts Center;Toyota Tire Center | K19: https://www.northbakersfieldtoyota.com/service/schedule-service/ | L19: Monday 7:00 am - 6:00 pm~Tuesday 7:00 am - 6:00 pm~Wednesday 7:00 am - 6:00 pm~Thursday 7:00 am - 6:00 pm~Friday 7:00 am - 6:00 pm~Saturday 7:00 am - 4:00 pm~ | N19: Jason Cronin | O19: Jason Cronin | P19: Service Manager | R19: 24-Hour Vehicle Drop Off | S19: Advanced Diagnostics | T19: Complimentary Ride Share | U19: EV Charging Station | V19: Late Pickup | W19: Online Scheduling | X19: 6616151100 | Y19: https://www.facebook.com/northbakersfieldtoyota/ | AA19: https://www.youtube.com/user/NBT04528 | AC19: https://www.instagram.com/north_bakersfield_toyota/ | AE19: https://www.toyotatirecenter.com/?uid=8764EBAB-9323-DE24-1ADE8F44AEACA74C | AF19: 2022-04-11 | AG19: 2025-12-19 | AH19: No Issue Detected
A20: 04284 | B20: Claremont Toyota | C20: 115 | D20: 909-542-1687 | E20: 601 Auto Center Drive | F20: Claremont | G20: CA | H20: 91711 | I20: https://www.claremonttoyota.com | J20: 24-Hour Vehicle Drop Off;Advanced Diagnostics;Advanced Tune-Up Equip.;Complimentary Beverages;Complimentary Ride Share;EV Charging Station;Auto Detailing;Express Lube;Express Maintenance;On-Site Rental Vehicles;Parts Center;Toyota Tire Center;Board of Governors Award;Pres. Customer 1st Award | K20: https://www.claremonttoyota.com/#modal-scheduleservice | L20: Monday 7:00 am - 7:00 pm~Tuesday 7:00 am - 7:00 pm~Wednesday 7:00 am - 7:00 pm~Thursday 7:00 am - 7:00 pm~Friday 7:00 am - 7:00 pm~Saturday 7:00 am - 5:00 pm~ | O20: Your Claremont Service Team | R20: 24-Hour Vehicle Drop Off | S20: Advanced Diagnostics | T20: Advanced Tune-Up Equip. | U20: Complimentary Beverages | V20: Complimentary Ride Share | W20: EV Charging Station | X20: 9096251500 | AE20: https://www.toyotatirecenter.com/?uid=F8C50940-990C-D256-B20C1B811C70100D | AF20: 2022-04-11 | AG20: 2026-05-06 | AH20: Same as Dealer_URL (homepage) | AJ20: https://www.claremonttoyota.com/inventory-cpo.json | AK20: Medium
A21: 04294 | B21: United Toyota | C21: 114 | D21: 760-457-0212 | E21: 2351 Highway 86 | F21: Imperial | G21: CA | H21: 92251 | I21: https://www.unitedtoyotaimperial.com | J21: 24-Hour Vehicle Drop Off;Advanced Diagnostics;Advanced Tune-Up Equip.;Children's Play Area;Online Scheduling;Pet Friendly | K21: https://www.unitedtoyotaimperial.com/service/ | L21: Monday 7:00 am - 6:00 pm~Tuesday 7:00 am - 6:00 pm~Wednesday 7:00 am - 6:00 pm~Thursday 7:00 am - 6:00 pm~Friday 7:00 am - 6:00 pm~Saturday 7:00 am - 6:00 pm~ | M21: service@unitedtoyotaimperial.com | R21: 24-Hour Vehicle Drop Off | S21: Advanced Diagnostics | T21: Advanced Tune-Up Equip. | U21: Children's Play Area | V21: Online Scheduling | W21: Pet Friendly | X21: 7603539300 | AE21: https://www.toyotatirecenter.com/?uid=B7489FF2-BA9E-43EE-B85BD33E154B883D | AF21: 2022-04-11 | AG21: 2026-06-08 | AH21: No Issue Detected
A22: 04374 | B22: Antioch Toyota | C22: 122 | D22: 925-778-4800 | E22: 1831 Auto Center Drvie | F22: Antioch | G22: CA | H22: 94509 | I22: https://www.antiochtoyota.com | J22: 24-Hour Vehicle Drop Off;Advanced Diagnostics;Advanced Tune-Up Equip.;Children's Play Area;Complimentary Beverages;Online Scheduling;Car Wash;Parts Center;RAV4 EV Service;Toyota Tire Center | K22: https://www.antiochtoyota.com/schedule-service.htm | L22: Monday 7:00 am - 6:00 pm~Tuesday 7:00 am - 6:00 pm~Wednesday 7:00 am - 6:00 pm~Thursday 7:00 am - 6:00 pm~Friday 7:00 am - 6:00 pm~Saturday 7:30 am - 5:00 pm~ | M22: jcarter@antiochtoyota.com | N22: Jonathon Carter | O22: Jonathan Carter | P22: Service Manager | R22: 24-Hour Vehicle Drop Off | S22: Advanced Diagnostics | T22: Advanced Tune-Up Equip. | U22: Children's Play Area | V22: Complimentary Beverages | W22: Online Scheduling | X22: 9257784800 | Y22: https://www.facebook.com/AntiochToyota | Z22: https://twitter.com/AntiochToyota | AA22: https://www.youtube.com/channel/UCE57cVv67XChxYom2SJxO2Q/about | AB22: https://www.yelp.com/biz/antioch-toyota-antioch | AE22: https://www.toyotatirecenter.com/?uid=7E531E1F-A184-446D-8378DEB9920E69D3 | AF22: 2022-04-11 | AG22: 2025-10-31 | AH22: Redirect Drops Query String | AI22: https://www.antiochtoyota.com/schedule-service.htm -> https://www.antiochtoyota.com/service/schedule-service/ (redirect drops query strings; confirmed by appending test params: https://www.antiochtoyota.com/schedule-service.htm?siteid=test&utm_source=test -> https://www.antiochtoyota.com/service/schedule-service/)
A23: 04454 | B23: Magnussen's Toyota of Palo Alto | C23: 121 | D23: 650-813-6121 | E23: 690 San Antonio Road | F23: Palo Alto | G23: CA | H23: 94306 | I23: https://www.toyotapaloalto.com | J23: Advanced Diagnostics;Advanced Tune-Up Equip.;Complimentary Ride Share;Online Scheduling;Spanish Speaking;Toyota Cert. Technicians;Express Lube;On-Site Rental Vehicles;Parts Center;RAV4 EV Service;Toyota Tire Center | K23: https://www.toyotapaloalto.com/schedule-service.htm | L23: Monday 7:00 am - 6:00 pm~Tuesday 7:00 am - 6:00 pm~Wednesday 7:00 am - 6:00 pm~Thursday 7:00 am - 6:00 pm~Friday 7:00 am - 6:00 pm~Saturday 7:00 am - 6:00 pm~ | M23: service@toyotapaloalto.com | O23: John Hausler | P23: Service Director | R23: Advanced Diagnostics | S23: Advanced Tune-Up Equip. | T23: Complimentary Ride Share | U23: Online Scheduling | V23: Spanish Speaking | W23: Toyota Cert. Technicians | X23: 6504942100 | Y23: https://www.facebook.com/toyotapaloalto | Z23: https://twitter.com/ToyotaPaloAlto | AA23: https://www.youtube.com/user/ToyotaOfPaloAlto | AB23: https://www.yelp.com/biz/magnussens-toyota-of-palo-alto-palo-alto | AE23: https://www.toyotatirecenter.com/?uid=C1F555AE-0F3D-0E7B-C4BE08D182251481 | AF23: 2022-04-11 | AG23: 2026-06-24 | AH23: No Issue Detected
A24: 04649 | B24: Toyota of Glendale | C24: 113 | D24: 818-244-4196 | E24: 1260 South Brand Blvd. | F24: Glendale | G24: CA | H24: 91204 | I24: https://www.toyotaofglendale.com | J24: 24-Hour Vehicle Drop Off;Advanced Diagnostics;Advanced Tune-Up Equip.;Complimentary Beverages;Complimentary Ride Share;Contactless Service;Auto Detailing;Express Lube;Express Maintenance;Mirai Service;On-Site Rental Vehicles;Parts Center;Pres. Customer 1st Award | K24: https://www.toyotaofglendale.com/toyota-schedule-service.htm | L24: Monday 7:00 am - 7:00 pm~Tuesday 7:00 am - 7:00 pm~Wednesday 7:00 am - 7:00 pm~Thursday 7:00 am - 7:00 pm~Friday 7:00 am - 7:00 pm~Saturday 8:00 am - 5:00 pm~ | M24: kris_toyotaofglendale@yahoo.com | O24: Robert Barahona | P24: Service Director | R24: 24-Hour Vehicle Drop Off | S24: Advanced Diagnostics | T24: Advanced Tune-Up Equip. | U24: Complimentary Beverages | V24: Complimentary Ride Share | W24: Contactless Service | X24: 8182444196 | Y24: https://www.facebook.com/glendaletoyota | Z24: https://twitter.com/glendaletoyota | AA24: https://www.youtube.com/channel/UC7dv0PKeSYT4d0JtBRSbYnQ | AB24: https://www.yelp.com/biz/oyota-of-glendale-glendale | AE24: https://www.toyotatirecenter.com/?uid=803E1BAD-2A46-4B50-9764661C41FA5136 | AF24: 2022-04-11 | AG24: 2026-06-08 | AH24: Redirect Drops Query String | AI24: https://www.toyotaofglendale.com/toyota-schedule-service.htm -> https://www.toyotaofglendale.com/service/schedule-service/ (redirect drops query strings; confirmed by appending test params: https://www.toyotaofglendale.com/toyota-schedule-service.htm?siteid=test&utm_source=test -> https://www.toyotaofglendale.com/service/schedule-service/)
A25: 04819 | B25: Temecula Valley Toyota | C25: 117 | D25: 951-695-0575 | E25: 26631 Ynez Road | F25: Temecula | G25: CA | H25: 92591 | I25: https://www.tvtoyota.com | J25: 24-Hour Vehicle Drop Off;Advanced Diagnostics;Advanced Tune-Up Equip.;Barista/Coffee Bar;Complimentary Beverages;Online Scheduling;Express Lube;Express Maintenance;Toyota Tire Center;Board of Governors Award;Pres. Customer 1st Award | K25: https://www.tvtoyota.com/schedule-service-appt.htm | L25: Monday 6:00 am - 5:00 pm~Tuesday 6:00 am - 5:00 pm~Wednesday 6:00 am - 5:00 pm~Thursday 6:00 am - 5:00 pm~Friday 6:00 am - 5:00 pm~Saturday 6:00 am - 5:00 pm~ | O25: Patrick Smith | P25: Service Manager | R25: 24-Hour Vehicle Drop Off | S25: Advanced Diagnostics | T25: Advanced Tune-Up Equip. | U25: Barista/Coffee Bar | V25: Complimentary Beverages | W25: Online Scheduling | X25: 9516940575 | Y25: https://www.facebook.com/toyotatemecula | Z25: https://twitter.com/tv_toyota | AA25: https://www.youtube.com/user/toyotaoftemecula | AB25: https://www.yelp.com/biz/temecula-valley-toyota-temecula-2 | AE25: https://www.toyotatirecenter.com/?uid=6C340654-A256-4F14-AE297D4C277E12C6 | AF25: 2022-04-11 | AG25: 2026-05-06 | AH25: Redirect Drops Query String | AI25: https://www.tvtoyota.com/schedule-service-appt.htm -> https://www.tvtoyota.com/schedule-service-online/ (redirect drops query strings; confirmed by appending test params: https://www.tvtoyota.com/schedule-service-appt.htm?siteid=test&utm_source=test -> https://www.tvtoyota.com/schedule-service-online/)
A26: 05071 | B26: McDonald Toyota | C26: 157 | D26: 970-339-3900 | E26: 4732 West 26th Street | F26: Greeley | G26: CO | H26: 80634 | I26: https://www.mcdonaldtoyotagreeley.com | J26: 24-Hour Vehicle Drop Off;Advanced Diagnostics;Advanced Tune-Up Equip.;Barista/Coffee Bar;Children's Play Area;Complimentary Beverages;Car Wash;Express Lube;Parts Center;RAV4 EV Service;Toyota Tire Center | K26: https://www.mcdonaldtoyotagreeley.com/schedule-service | L26: Monday 7:30 am - 6:00 pm~Tuesday 7:30 am - 6:00 pm~Wednesday 7:30 am - 6:00 pm~Thursday 7:30 am - 6:00 pm~Friday 7:30 am - 6:00 pm~Saturday 8:00 am - 4:00 pm~ | O26: Your Service Center | R26: 24-Hour Vehicle Drop Off | S26: Advanced Diagnostics | T26: Advanced Tune-Up Equip. | U26: Barista/Coffee Bar | V26: Children's Play Area | W26: Complimentary Beverages | X26: 9703393900 | AE26: https://www.toyotatirecenter.com/?uid=F4099638-031A-5E8A-EA1EF55293E1C3CB | AF26: 2022-04-11 | AG26: 2026-07-07 | AH26: No Issue Detected
A27: 06036 | B27: Middletown Toyota | C27: 164 | D27: 860-347-7294 | E27: 634 Newfield Street | F27: Middletown | G27: CT | H27: 06457 | I27: https://www.middletowntoyota.com | J27: 24-Hour Vehicle Drop Off;Advanced Diagnostics;Advanced Tune-Up Equip.;Barista/Coffee Bar;Late Pickup;Online Scheduling;Auto Detailing;Car Wash;On-Site Rental Vehicles;Parts Center;RAV4 EV Service;Toyota Tire Center;Pres. Customer 1st Award | K27: https://www.middletowntoyota.com/schedule-service | L27: Monday 7:00 am - 6:00 pm~Tuesday 7:00 am - 6:00 pm~Wednesday 7:00 am - 6:00 pm~Thursday 7:00 am - 6:00 pm~Friday 7:00 am - 6:00 pm~Saturday 7:00 am - 2:00 pm~ | M27: service@middletowntoyota.com | O27: Your Service Professionals | P27: Middletown Toyota | R27: 24-Hour Vehicle Drop Off | S27: Advanced Diagnostics | T27: Advanced Tune-Up Equip. | U27: Barista/Coffee Bar | V27: Late Pickup | W27: Online Scheduling | X27: 8603477294 | Y27: https://www.facebook.com/MiddletownToyota | Z27: https://twitter.com/middtoyota | AA27: https://www.youtube.com/user/Middletowntoyota1975 | AB27: https://www.yelp.com/biz/middletown-toyota-middletown | AC27: https://www.instagram.com/middletowntoyota/ | AF27: 2022-04-11 | AG27: 2026-05-06 | AH27: Unreachable / Timeout | AI27: ('Connection aborted.', RemoteDisconnected('Remote end closed connection without response')) | browser fallback unavailable: Page.goto: Timeout 20000ms exceeded. Call log: - navigating to "https://w
A28: 06037 | B28: Charles Toyota | C28: 164 | D28: 860-889-8375 | E28: 500 West Thames Street | F28: Norwich | G28: CT | H28: 06360 | I28: https://www.charlestoyota.com | J28: 24-Hour Vehicle Drop Off;Advanced Diagnostics;Advanced Tune-Up Equip.;Barista/Coffee Bar;Complimentary Beverages;Contactless Service;Express Lube;Parts Center;Toyota Collision Center;Toyota Tire Center | K28: https://www.charlestoyota.com/#modal-scheduleservice | L28: Monday 7:30 am - 5:00 pm~Tuesday 7:30 am - 5:00 pm~Wednesday 7:30 am - 5:00 pm~Thursday 7:30 am - 5:00 pm~Friday 7:30 am - 5:00 pm~Saturday 7:30 am - 12:30 pm~ | M28: service@charlestoyota.com | O28: Your Service Professionals | P28: Service Director | R28: 24-Hour Vehicle Drop Off | S28: Advanced Diagnostics | T28: Advanced Tune-Up Equip. | U28: Barista/Coffee Bar | V28: Complimentary Beverages | W28: Contactless Service | X28: 8608898375 | Y28: https://www.facebook.com/Charles.ToyotaCT/ | Z28: https://twitter.com/Charles_Toyota | AA28: https://www.youtube.com/user/charlestoyota | AB28: https://www.yelp.com/biz/charles-toyota-norwich-2 | AE28: https://www.toyotatirecenter.com/?uid=016A42E5-BE66-1FA4-F54572CBE472B43C | AF28: 2022-04-11 | AG28: 2026-05-06 | AH28: Same as Dealer_URL (homepage) | AK28: Low (candidates found but none loaded cleanly)
A29: 06042 | B29: Hoffman Toyota | C29: 164 | D29: 860-651-0207 | E29: 36 Albany Turnpike Rt 44 | F29: West Simsbury | G29: CT | H29: 06092 | I29: https://www.hoffmantoyota.com | J29: 24-Hour Vehicle Drop Off;Advanced Diagnostics;Advanced Tune-Up Equip.;Barista/Coffee Bar;Collision Loaner Vehicle;Complimentary Beverages;Auto Detailing;Parts Center;RAV4 EV Service;Toyota Collision Center;Toyota Tire Center;Pres. Customer 1st Award | K29: https://www.hoffmantoyota.com/Service_Toyota_Appt.htm | L29: Monday 7:00 am - 5:30 pm~Tuesday 7:00 am - 5:30 pm~Wednesday 7:00 am - 5:30 pm~Thursday 7:00 am - 5:30 pm~Friday 7:00 am - 5:30 pm~Saturday 7:30 am - 3:30 pm~ | M29: toyotaservice@hoffmanauto.com | O29: Mike Fitzgerald | P29: Service Manager | R29: 24-Hour Vehicle Drop Off | S29: Advanced Diagnostics | T29: Advanced Tune-Up Equip. | U29: Barista/Coffee Bar | V29: Collision Loaner Vehicle | W29: Complimentary Beverages | X29: 8606513725 | Y29: https://www.facebook.com/hoffmantoyota | Z29: https://twitter.com/HoffmanToyota | AA29: https://www.youtube.com/channel/UC2x_AcVG3AT5JPvxN6CWl7Q | AB29: https://www.yelp.com/biz/hoffman-toyota-west-simsbury | AC29: https://instagram.com/hoffmantoyota | AE29: https://www.toyotatirecenter.com/?uid=F1176E64-C03C-4166-8BB44C7543408EE0 | AF29: 2022-04-11 | AG29: 2024-07-25 | AH29: No Issue Detected
A30: 24026 | B30: Adams Toyota Lee's Summit | C30: 231 | D30: 816-358-7600 | E30: 501 N.E. Colbern Road | F30: Lee's Summit | G30: MO | H30: 64086 | I30: https://www.adamstoyota.com | J30: 24-Hour Vehicle Drop Off;Advanced Diagnostics;Advanced Tune-Up Equip.;Barista/Coffee Bar;Complimentary Beverages;Online Scheduling;Car Wash;Parts Center;Toyota Collision Center;Toyota Tire Center | K30: https://www.adamstoyota.com/service-appointment/ | L30: Monday 7:00 am - 6:00 pm~Tuesday 7:00 am - 6:00 pm~Wednesday 7:00 am - 6:00 pm~Thursday 7:00 am - 6:00 pm~Friday 7:00 am - 6:00 pm~Saturday 7:00 am - 4:00 pm~ | M30: ssweeney@adamsautogroup.com | O30: Shawn Sweeney | P30: Service Manager | R30: 24-Hour Vehicle Drop Off | S30: Advanced Diagnostics | T30: Advanced Tune-Up Equip. | U30: Barista/Coffee Bar | V30: Complimentary Beverages | W30: Online Scheduling | X30: 8163587600 | Y30: https://www.facebook.com/Adams-Toyota-Scion-74439592341 | Z30: https://twitter.com/AdamsToyota1 | AA30: https://www.youtube.com/channel/UCNLpE8xTQTBrkd0ddZulSug/videos | AB30: https://www.yelp.com/biz/adams-toyota-lees-summit | AE30: https://www.toyotatirecenter.com/?uid=0C22F017-0AEF-034F-6B7AAED9AAD6E042 | AF30: 2022-04-11 | AG30: 2025-09-16 | AH30: Error Page Entered | AI30: Status 403 at https://www.adamstoyota.com/service-appointment/ | AK30: None (no sitemap found; homepage links yielded no candidates)
A31: 24059 | B31: Baldwin Toyota | C31: 233 | D31: 573-785-6484 | E31: 801 S. Westwood Blvd. | F31: Poplar Bluff | G31: MO | H31: 63901 | I31: https://www.baldwintoyota.com | J31: 24-Hour Vehicle Drop Off;Advanced Diagnostics;Advanced Tune-Up Equip.;Barista/Coffee Bar;Complimentary Beverages;Contactless Service;Car Wash;Mirai Service;On-Site Rental Vehicles;Parts Center;RAV4 EV Service;State Cert. Inspection;Pres. Customer 1st Award | K31: https://www.baldwintoyota.com/service-appointment/ | L31: Monday 7:30 am - 5:00 pm~Tuesday 7:30 am - 5:00 pm~Wednesday 7:30 am - 5:00 pm~Thursday 7:30 am - 5:00 pm~Friday 7:30 am - 5:00 pm~Saturday 8:00 am - 12:00 pm~ | O31: David Allen | P31: Service Manager | R31: 24-Hour Vehicle Drop Off | S31: Advanced Diagnostics | T31: Advanced Tune-Up Equip. | U31: Barista/Coffee Bar | V31: Complimentary Beverages | W31: Contactless Service | X31: 5737856484 | Y31: https://www.facebook.com/baldwintoyota/timeline | Z31: https://twitter.com/BaldwinToyota | AA31: https://www.youtube.com/channel/UC22W4lViANRgQsbpK0f9ojQ | AB31: https://www.yelp.com/biz/baldwin-toyota-poplar-bluff-2 | AE31: https://www.toyotatirecenter.com/?uid=2E28ACBA-AFCA-4395-9E57E17B3E0ED341 | AF31: 2022-04-11 | AG31: 2026-05-06 | AH31: Error Page Entered | AI31: Status 403 at https://www.baldwintoyota.com/service-appointment/ | AK31: None (no sitemap found; homepage links yielded no candidates)
A32: 24071 | B32: Reliable Toyota | C32: 233 | D32: 833-685-4262 | E32: 3521 East Sunshine | F32: Springfield | G32: MO | H32: 65809 | I32: https://www.reliabletoyotamo.com | J32: 24-Hour Vehicle Drop Off;Advanced Diagnostics;Advanced Tune-Up Equip.;Barista/Coffee Bar;Children's Play Area;Complimentary Beverages;Auto Detailing;Car Wash;Express Lube;Express Maintenance;On-Site Rental Vehicles;Parts Center;Board of Governors Award | K32: https://www.reliabletoyotamo.com/service/appointment-form.htm | L32: Monday 7:30 am - 5:30 pm~Tuesday 7:30 am - 5:30 pm~Wednesday 7:30 am - 5:30 pm~Thursday 7:30 am - 5:30 pm~Friday 7:30 am - 5:30 pm~Saturday 8:00 am - 5:00 pm~ | M32: internetsales@reliablesuperstore.com | R32: 24-Hour Vehicle Drop Off | S32: Advanced Diagnostics | T32: Advanced Tune-Up Equip. | U32: Barista/Coffee Bar | V32: Children's Play Area | W32: Complimentary Beverages | X32: 4178899000 | Y32: https://www.facebook.com/reliabletoyota | Z32: https://twitter.com/ToyotaofSPD | AA32: https://www.youtube.com/user/ReliableSuperstore/about | AB32: https://www.yelp.com/biz/reliable-toyota-springfield | AE32: https://www.toyotatirecenter.com/?uid=E71F366A-9F82-69EC-97FD978938141ACA | AF32: 2022-04-11 | AG32: 2026-05-06 | AH32: No Issue Detected
A33: 25056 | B33: City Toyota | C33: 137 | D33: 406-761-4900 | E33: 3900 10th Avenue South | F33: Great Falls | G33: MT | H33: 59405 | I33: https://www.city-toyota.com | J33: 24-Hour Vehicle Drop Off;Advanced Diagnostics;Advanced Tune-Up Equip.;Barista/Coffee Bar;Complimentary Snacks;Contactless Service;Auto Detailing;Car Wash;Express Lube;Express Maintenance;Parts Center;Toyota Collision Center | K33: https://www.city-toyota.com/service-appointment/ | L33: Monday 7:30 am - 6:00 pm~Tuesday 7:30 am - 6:00 pm~Wednesday 7:30 am - 6:00 pm~Thursday 7:30 am - 6:00 pm~Friday 7:30 am - 6:00 pm~~ | O33: Service Manager | R33: 24-Hour Vehicle Drop Off | S33: Advanced Diagnostics | T33: Advanced Tune-Up Equip. | U33: Barista/Coffee Bar | V33: Complimentary Snacks | W33: Contactless Service | X33: 4067614900 | Y33: https://www.facebook.com/City-Toyota-285174657657 | Z33: https://twitter.com/citytoyotamt | AA33: https://www.youtube.com/channel/UC84VeMszhAJCwOKftkrZI6Q | AB33: https://www.yelp.com/biz/city-toyota-great-falls | AE33: https://www.toyotatirecenter.com/?uid=40EF38F1-2D04-4953-95A26FDCB698FC96 | AF33: 2022-04-11 | AG33: 2026-02-02 | AH33: No Issue Detected
A34: 25060 | B34: Toyota of Bozeman | C34: 137 | D34: 406-585-2002 | E34: 8476 Huffine Lane | F34: Bozeman | G34: MT | H34: 59718 | I34: https://www.toyotaofbozeman.com | J34: 24-Hour Vehicle Drop Off;Advanced Diagnostics;Advanced Tune-Up Equip.;Complimentary Beverages;Contactless Service;Online Scheduling;Auto Detailing;Car Wash;Express Lube;Express Maintenance;On-Site Rental Vehicles;Parts Center;Pres. Customer 1st Award | K34: https://www.toyotaofbozeman.com/?schedule=true | L34: Monday 7:30 am - 6:00 pm~Tuesday 7:30 am - 6:00 pm~Wednesday 7:30 am - 6:00 pm~Thursday 7:30 am - 6:00 pm~Friday 7:30 am - 6:00 pm~Saturday 8:00 am - 5:00 pm~ | M34: cparsch@resslermotors.com | R34: 24-Hour Vehicle Drop Off | S34: Advanced Diagnostics | T34: Advanced Tune-Up Equip. | U34: Complimentary Beverages | V34: Contactless Service | W34: Online Scheduling | X34: 4065852002 | Y34: https://www.facebook.com/bozemantoyota/timeline | Z34: https://twitter.com/toyotaofbozeman | AA34: https://www.youtube.com/channel/UCKEQ7KmWCdRtVI5b9DSDAaw | AB34: https://www.yelp.com/biz/toyota-of-bozeman-bozeman | AF34: 2022-04-11 | AG34: 2026-06-08 | AH34: Same as Dealer_URL (homepage) | AJ34: https://www.toyotaofbozeman.com/vehicle-finder-service/ | AK34: High
A35: 25068 | B35: Toyota of Helena | C35: 137 | D35: 406-430-6904 | E35: 3365 Highway 12 East | F35: Helena | G35: MT | H35: 59601 | I35: https://www.toyotaofhelena.com | J35: 24-Hour Vehicle Drop Off;Advanced Diagnostics;Complimentary Beverages;Complimentary Snacks;Online Scheduling;Pet Friendly;On-Site Rental Vehicles;Parts Center | K35: https://www.toyotaofhelena.com/service/ | L35: Monday 7:00 am - 6:00 pm~Tuesday 7:00 am - 6:00 pm~Wednesday 7:00 am - 6:00 pm~Thursday 7:00 am - 6:00 pm~Friday 7:00 am - 6:00 pm~Saturday 7:00 am - 5:00 pm~ | M35: HMITTON@HELENATOYOTA.COM | N35: Horald Mitton | O35: Your "No Problem" Dealership | R35: 24-Hour Vehicle Drop Off | S35: Advanced Diagnostics | T35: Complimentary Beverages | U35: Complimentary Snacks | V35: Online Scheduling | W35: Pet Friendly | X35: 4064426310 | Y35: https://www.facebook.com/helenatoyota | AA35: https://www.youtube.com/@ToyotaOfHelena | AB35: https://www.yelp.com/biz/toyota-of-helena-helena | AD35: https://www.toyotaofhelena.com/new-vehicles/ | AE35: https://www.toyotatirecenter.com/?uid=83A13E3F-99AF-FF2C-94EA0B142255C951 | AF35: 2022-08-02 | AG35: 2026-06-08 | AH35: No Issue Detected
A36: 26024 | B36: Baxter Toyota of Lincoln | C36: 235 | D36: 402-476-4001 | E36: 8600 South 33rd Street | F36: Lincoln | G36: NE | H36: 68516 | I36: https://www.toyotaoflincoln.com | J36: 24-Hour Vehicle Drop Off;Advanced Diagnostics;Advanced Tune-Up Equip.;Barista/Coffee Bar;Complimentary Beverages;Online Scheduling;Auto Detailing;Express Lube;Express Maintenance;Parts Center;Toyota Tire Center;Pres. Customer 1st Award | K36: https://www.toyotaoflincoln.com/service/schedule-service/ | L36: Monday 6:00 am - 6:00 pm~Tuesday 6:00 am - 6:00 pm~Wednesday 6:00 am - 6:00 pm~Thursday 6:00 am - 6:00 pm~Friday 6:00 am - 6:00 pm~Saturday 6:00 am - 3:00 pm~ | M36: service@performancetoyotaoflincoln.com | N36: Matt Quimby | O36: Matt Quimby | P36: Service Manager | R36: 24-Hour Vehicle Drop Off | S36: Advanced Diagnostics | T36: Advanced Tune-Up Equip. | U36: Barista/Coffee Bar | V36: Complimentary Beverages | W36: Online Scheduling | X36: 4024764000 | Y36: https://www.facebook.com/BaxterToyotaLincoln | Z36: https://twitter.com/toyotalincoln | AA36: https://www.youtube.com/channel/UCrdSakUdSrqXbd8_9WocAhA | AB36: https://www.yelp.com/biz/performance-toyota-scion-of-lincoln-lincoln | AF36: 2022-04-11 | AG36: 2026-06-08 | AH36: No Issue Detected
A37: 39040 | B37: Stokes Toyota Beaufort | C37: 50G | D37: 843-522-3232 | E37: 3557 Trask Parkway | F37: Beaufort | G37: SC | H37: 29906 | I37: https://www.stokestoyotabeaufort.com | J37: Spanish Speaking;Toyota Tire Center | K37: https://www.stokestoyotabeaufort.com/service/schedule-service/ | L37: Monday 7:30 am - 6:00 pm~Tuesday 7:30 am - 6:00 pm~Wednesday 7:30 am - 6:00 pm~Thursday 7:30 am - 6:00 pm~Friday 7:30 am - 6:00 pm~Saturday 7:30 am - 4:00 pm~ | R37: Spanish Speaking | X37: 8435223232 | Y37: https://www.facebook.com/stokesbrowntoyotabft | Z37: https://twitter.com/StokesBrown | AA37: https://www.youtube.com/user/stokesbrowntoyotab | AB37: https://www.yelp.com/biz/stokes-brown-toyota-scion-beaufort | AC37: https://www.instagram.com/stokesbrowntoyotab | AE37: https://www.settirecenters.com/?uid=DBA9A759-70F8-43F9-B223BC18897A76CF | AF37: 2022-04-11 | AG37: 2026-05-06 | AH37: No Issue Detected
A38: 41043 | B38: Principle Toyota | C38: 228 | D38: 901-758-4040 | E38: 7370 Winchester Road | F38: Memphis | G38: TN | H38: 38125 | I38: https://www.principletoyota.com | J38: 24-Hour Vehicle Drop Off;Advanced Diagnostics;Advanced Tune-Up Equip.;Barista/Coffee Bar;Child Car Seat Check;Children's Play Area;Auto Detailing;Express Lube;On-Site Rental Vehicles;Parts Center;Toyota Tire Center | K38: https://www.principletoyota.com/service-scheduler.htm | L38: Monday 7:00 am - 6:00 pm~Tuesday 7:00 am - 6:00 pm~Wednesday 7:00 am - 6:00 pm~Thursday 7:00 am - 6:00 pm~Friday 7:00 am - 6:00 pm~Saturday 7:00 am - 5:00 pm~ | M38: dmontgomery@principleautomotive.com | O38: David Montgomery | P38: Service Director | R38: 24-Hour Vehicle Drop Off | S38: Advanced Diagnostics | T38: Advanced Tune-Up Equip. | U38: Barista/Coffee Bar | V38: Child Car Seat Check | W38: Children's Play Area | X38: 9017584040 | Y38: https://www.facebook.com/principletoyotaofmemphis | Z38: https://twitter.com/PrincipleToyota | AA38: https://www.youtube.com/channel/UCVF6qdfibXUTzyJEx-0zw3g | AB38: https://www.yelp.com/biz/principle-toyota-memphis-2 | AE38: https://www.toyotatirecenter.com/?uid=98B71AE5-FC6A-F31E-3739725B11A28648 | AF38: 2022-04-11 | AG38: 2026-02-20 | AH38: No Issue Detected
A39: 41056 | B39: Toyota of Cleveland | C39: 2210 | D39: 423-339-1138 | E39: 3560 Village North Bl SW | F39: McDonald | G39: TN | H39: 37353 | I39: https://www.toyotaofcleveland.com | J39: 24-Hour Vehicle Drop Off;Advanced Diagnostics;Advanced Tune-Up Equip.;Barista/Coffee Bar;Children's Play Area;Complimentary Beverages;Auto Detailing;Car Wash;Express Lube;Express Maintenance;Parts Center;Toyota Tire Center;Pres. Customer 1st Award | K39: https://www.toyotaofcleveland.com/service/scheduler.htm | L39: Monday 7:00 am - 6:00 pm~Tuesday 7:00 am - 6:00 pm~Wednesday 7:00 am - 6:00 pm~Thursday 7:00 am - 6:00 pm~Friday 7:00 am - 6:00 pm~Saturday 8:00 am - 4:00 pm~ | M39: tomtrout@toyotaofcleveland.com | R39: 24-Hour Vehicle Drop Off | S39: Advanced Diagnostics | T39: Advanced Tune-Up Equip. | U39: Barista/Coffee Bar | V39: Children's Play Area | W39: Complimentary Beverages | X39: 4233391138 | Y39: https://www.facebook.com/ToyotaofCleveland | Z39: https://twitter.com/toyotafun | AA39: https://www.youtube.com/channel/UC7Y7wTx0G8OjQw25k7dtXFw | AB39: https://www.yelp.com/biz/toyota-of-cleveland-mc-donald | AC39: https://www.instagram.com/toyota.of.cleveland/?hl=en | AE39: https://www.toyotatirecenter.com/?uid=AFF72729-FE4B-3BD1-60CE9153432DDD99 | AF39: 2022-04-11 | AG39: 2026-06-08 | AH39: No Issue Detected
A40: 41061 | B40: Rick McGill's Airport Toyota | C40: 2210 | D40: 888-213-4062 | E40: 3145 Alcoa Highway | F40: Alcoa | G40: TN | H40: 37701 | I40: https://www.rickmcgillairporttoyota.com | J40: 24-Hour Vehicle Drop Off;Advanced Diagnostics;Advanced Tune-Up Equip.;Barista/Coffee Bar;Complimentary Beverages;Complimentary Snacks;Auto Detailing;Express Maintenance;On-Site Rental Vehicles;Parts Center;Toyota Tire Center | K40: https://www.rickmcgillairporttoyota.com/ | L40: Monday 7:00 am - 6:00 pm~Tuesday 7:00 am - 6:00 pm~Wednesday 7:00 am - 6:00 pm~Thursday 7:00 am - 6:00 pm~Friday 7:00 am - 6:00 pm~Saturday 7:30 am - 4:00 pm~ | M40: sales@rickmcgillsairporttoyota.edealerhub.com | N40: Gary Sergent | O40: Rick Mcgill | P40: President | R40: 24-Hour Vehicle Drop Off | S40: Advanced Diagnostics | T40: Advanced Tune-Up Equip. | U40: Barista/Coffee Bar | V40: Complimentary Beverages | W40: Complimentary Snacks | X40: 8659702615 | Y40: https://www.facebook.com/RickMcGillsAirportToyotaScion | Z40: https://twitter.com/mcgilltoyota | AA40: https://www.youtube.com/@rickmcgillairporttoyota | AB40: https://www.yelp.com/biz/mcgills-rick-airport-toyota-alcoa | AD40: https://www.rickmcgillairporttoyota.com/toyota-alcoa-tn.html | AE40: https://www.toyotatirecenter.com/?uid=2A16900D-0AA3-A0F8-34F9EBD358A0E62E | AF40: 2022-04-11 | AG40: 2026-05-06 | AH40: Same as Dealer_URL (homepage) | AJ40: https://www.rickmcgillairporttoyota.com/toyota-schedule-service.htm | AK40: High
...

Sheet Summary
A1: Error Type | B1: Count | C1: New Error | D1: Comments | E1: Count of suggested URL | I1: Comments
E2: High | F2: Medium | G2: Low | H2: None
A3: {=_xlfn._xlws.SORT(_xlfn.UNIQUE(_xlfn._xlws.FILTER('AMP Dealer Profile Data'!AH:AH,'AMP Dealer Profile Data'!AH:AH<>"")))} -> 3rd Party Scheduler | B3: =COUNTIF('AMP Dealer Profile Data'!AH:AH,A3) -> 23 | D3: Only listed domains are identified | E3: =COUNTIFS('AMP Dealer Profile Data'!$AH:$AH,$A3,'AMP Dealer Profile Data'!$AK:$AK,"High") -> 0 | F3: =COUNTIFS('AMP Dealer Profile Data'!$AH:$AH,$A3,'AMP Dealer Profile Data'!$AK:$AK,"Medium") -> 0 | G3: =COUNTIFS('AMP Dealer Profile Data'!$AH:$AH,$A3,'AMP Dealer Profile Data'!$AK:$AK,"Low (candidates found but none loaded cleanly)") -> 0 | H3: =COUNTIFS('AMP Dealer Profile Data'!$AH:$AH,$A3,'AMP Dealer Profile Data'!$AK:$AK,"None (no sitemap found; homepage links yielded no candidates)") -> 0
A4: Different Domain (Unverified) | B4: =COUNTIF('AMP Dealer Profile Data'!AH:AH,A4) -> 43 | C4: Yes | D4: The service URL is redirecting to the actual domain but is not identified | E4: =COUNTIFS('AMP Dealer Profile Data'!$AH:$AH,$A4,'AMP Dealer Profile Data'!$AK:$AK,"High") -> 0 | F4: =COUNTIFS('AMP Dealer Profile Data'!$AH:$AH,$A4,'AMP Dealer Profile Data'!$AK:$AK,"Medium") -> 0 | G4: =COUNTIFS('AMP Dealer Profile Data'!$AH:$AH,$A4,'AMP Dealer Profile Data'!$AK:$AK,"Low (candidates found but none loaded cleanly)") -> 0 | H4: =COUNTIFS('AMP Dealer Profile Data'!$AH:$AH,$A4,'AMP Dealer Profile Data'!$AK:$AK,"None (no sitemap found; homepage links yielded no candidates)") -> 0
A5: Error Page Entered | B5: =COUNTIF('AMP Dealer Profile Data'!AH:AH,A5) -> 159 | E5: =COUNTIFS('AMP Dealer Profile Data'!$AH:$AH,$A5,'AMP Dealer Profile Data'!$AK:$AK,"High") -> 30 | F5: =COUNTIFS('AMP Dealer Profile Data'!$AH:$AH,$A5,'AMP Dealer Profile Data'!$AK:$AK,"Medium") -> 10 | G5: =COUNTIFS('AMP Dealer Profile Data'!$AH:$AH,$A5,'AMP Dealer Profile Data'!$AK:$AK,"Low (candidates found but none loaded cleanly)") -> 2 | H5: =COUNTIFS('AMP Dealer Profile Data'!$AH:$AH,$A5,'AMP Dealer Profile Data'!$AK:$AK,"None (no sitemap found; homepage links yielded no candidates)") -> 117
A6: Error_Type | B6: =COUNTIF('AMP Dealer Profile Data'!AH:AH,A6) -> 1 | E6: =COUNTIFS('AMP Dealer Profile Data'!$AH:$AH,$A6,'AMP Dealer Profile Data'!$AK:$AK,"High") -> 0 | F6: =COUNTIFS('AMP Dealer Profile Data'!$AH:$AH,$A6,'AMP Dealer Profile Data'!$AK:$AK,"Medium") -> 0 | G6: =COUNTIFS('AMP Dealer Profile Data'!$AH:$AH,$A6,'AMP Dealer Profile Data'!$AK:$AK,"Low (candidates found but none loaded cleanly)") -> 0 | H6: =COUNTIFS('AMP Dealer Profile Data'!$AH:$AH,$A6,'AMP Dealer Profile Data'!$AK:$AK,"None (no sitemap found; homepage links yielded no candidates)") -> 0
A7: No Issue Detected | B7: =COUNTIF('AMP Dealer Profile Data'!AH:AH,A7) -> 620 | E7: =COUNTIFS('AMP Dealer Profile Data'!$AH:$AH,$A7,'AMP Dealer Profile Data'!$AK:$AK,"High") -> 0 | F7: =COUNTIFS('AMP Dealer Profile Data'!$AH:$AH,$A7,'AMP Dealer Profile Data'!$AK:$AK,"Medium") -> 0 | G7: =COUNTIFS('AMP Dealer Profile Data'!$AH:$AH,$A7,'AMP Dealer Profile Data'!$AK:$AK,"Low (candidates found but none loaded cleanly)") -> 0 | H7: =COUNTIFS('AMP Dealer Profile Data'!$AH:$AH,$A7,'AMP Dealer Profile Data'!$AK:$AK,"None (no sitemap found; homepage links yielded no candidates)") -> 0
A8: No URL | B8: =COUNTIF('AMP Dealer Profile Data'!AH:AH,A8) -> 58 | E8: =COUNTIFS('AMP Dealer Profile Data'!$AH:$AH,$A8,'AMP Dealer Profile Data'!$AK:$AK,"High") -> 50 | F8: =COUNTIFS('AMP Dealer Profile Data'!$AH:$AH,$A8,'AMP Dealer Profile Data'!$AK:$AK,"Medium") -> 4 | G8: =COUNTIFS('AMP Dealer Profile Data'!$AH:$AH,$A8,'AMP Dealer Profile Data'!$AK:$AK,"Low (candidates found but none loaded cleanly)") -> 0 | H8: =COUNTIFS('AMP Dealer Profile Data'!$AH:$AH,$A8,'AMP Dealer Profile Data'!$AK:$AK,"None (no sitemap found; homepage links yielded no candidates)") -> 4
A9: Query String Dropped on Append | B9: =COUNTIF('AMP Dealer Profile Data'!AH:AH,A9) -> 1 | E9: =COUNTIFS('AMP Dealer Profile Data'!$AH:$AH,$A9,'AMP Dealer Profile Data'!$AK:$AK,"High") -> 0 | F9: =COUNTIFS('AMP Dealer Profile Data'!$AH:$AH,$A9,'AMP Dealer Profile Data'!$AK:$AK,"Medium") -> 0 | G9: =COUNTIFS('AMP Dealer Profile Data'!$AH:$AH,$A9,'AMP Dealer Profile Data'!$AK:$AK,"Low (candidates found but none loaded cleanly)") -> 0 | H9: =COUNTIFS('AMP Dealer Profile Data'!$AH:$AH,$A9,'AMP Dealer Profile Data'!$AK:$AK,"None (no sitemap found; homepage links yielded no candidates)") -> 0
A10: Query String Renders Error Page | B10: =COUNTIF('AMP Dealer Profile Data'!AH:AH,A10) -> 5 | D10: Redirection in the base URL itself; the append does not follow that same redirect, leading to error | E10: =COUNTIFS('AMP Dealer Profile Data'!$AH:$AH,$A10,'AMP Dealer Profile Data'!$AK:$AK,"High") -> 0 | F10: =COUNTIFS('AMP Dealer Profile Data'!$AH:$AH,$A10,'AMP Dealer Profile Data'!$AK:$AK,"Medium") -> 0 | G10: =COUNTIFS('AMP Dealer Profile Data'!$AH:$AH,$A10,'AMP Dealer Profile Data'!$AK:$AK,"Low (candidates found but none loaded cleanly)") -> 0 | H10: =COUNTIFS('AMP Dealer Profile Data'!$AH:$AH,$A10,'AMP Dealer Profile Data'!$AK:$AK,"None (no sitemap found; homepage links yielded no candidates)") -> 0
A11: Query String Test Failed (network error) | B11: =COUNTIF('AMP Dealer Profile Data'!AH:AH,A11) -> 2 | C11: Yes | D11: Subject to change with each validation | E11: =COUNTIFS('AMP Dealer Profile Data'!$AH:$AH,$A11,'AMP Dealer Profile Data'!$AK:$AK,"High") -> 0 | F11: =COUNTIFS('AMP Dealer Profile Data'!$AH:$AH,$A11,'AMP Dealer Profile Data'!$AK:$AK,"Medium") -> 0 | G11: =COUNTIFS('AMP Dealer Profile Data'!$AH:$AH,$A11,'AMP Dealer Profile Data'!$AK:$AK,"Low (candidates found but none loaded cleanly)") -> 0 | H11: =COUNTIFS('AMP Dealer Profile Data'!$AH:$AH,$A11,'AMP Dealer Profile Data'!$AK:$AK,"None (no sitemap found; homepage links yielded no candidates)") -> 0
A12: Redirect Drops Query String | B12: =COUNTIF('AMP Dealer Profile Data'!AH:AH,A12) -> 167 | E12: =COUNTIFS('AMP Dealer Profile Data'!$AH:$AH,$A12,'AMP Dealer Profile Data'!$AK:$AK,"High") -> 0 | F12: =COUNTIFS('AMP Dealer Profile Data'!$AH:$AH,$A12,'AMP Dealer Profile Data'!$AK:$AK,"Medium") -> 0 | G12: =COUNTIFS('AMP Dealer Profile Data'!$AH:$AH,$A12,'AMP Dealer Profile Data'!$AK:$AK,"Low (candidates found but none loaded cleanly)") -> 0 | H12: =COUNTIFS('AMP Dealer Profile Data'!$AH:$AH,$A12,'AMP Dealer Profile Data'!$AK:$AK,"None (no sitemap found; homepage links yielded no candidates)") -> 0
A13: Same as Dealer_URL (homepage) | B13: =COUNTIF('AMP Dealer Profile Data'!AH:AH,A13) -> 163 | D13: In some cases, the service module is refferenced within the homepage. The suggested URL may differ or remain the same in the case of single-page websites | E13: =COUNTIFS('AMP Dealer Profile Data'!$AH:$AH,$A13,'AMP Dealer Profile Data'!$AK:$AK,"High") -> 141 | F13: =COUNTIFS('AMP Dealer Profile Data'!$AH:$AH,$A13,'AMP Dealer Profile Data'!$AK:$AK,"Medium") -> 8 | G13: =COUNTIFS('AMP Dealer Profile Data'!$AH:$AH,$A13,'AMP Dealer Profile Data'!$AK:$AK,"Low (candidates found but none loaded cleanly)") -> 9 | H13: =COUNTIFS('AMP Dealer Profile Data'!$AH:$AH,$A13,'AMP Dealer Profile Data'!$AK:$AK,"None (no sitemap found; homepage links yielded no candidates)") -> 4 | I13: In some cases, the service module is refferenced within the homepage. The suggested URL may differ or remain the same in the case of single-page websites
A14: Tracking Appends Entered | B14: =COUNTIF('AMP Dealer Profile Data'!AH:AH,A14) -> 2 | E14: =COUNTIFS('AMP Dealer Profile Data'!$AH:$AH,$A14,'AMP Dealer Profile Data'!$AK:$AK,"High") -> 0 | F14: =COUNTIFS('AMP Dealer Profile Data'!$AH:$AH,$A14,'AMP Dealer Profile Data'!$AK:$AK,"Medium") -> 0 | G14: =COUNTIFS('AMP Dealer Profile Data'!$AH:$AH,$A14,'AMP Dealer Profile Data'!$AK:$AK,"Low (candidates found but none loaded cleanly)") -> 0 | H14: =COUNTIFS('AMP Dealer Profile Data'!$AH:$AH,$A14,'AMP Dealer Profile Data'!$AK:$AK,"None (no sitemap found; homepage links yielded no candidates)") -> 0
A15: Unreachable / Timeout | B15: =COUNTIF('AMP Dealer Profile Data'!AH:AH,A15) -> 25 | C15: Yes | D15: Subject to change with each validation | E15: =COUNTIFS('AMP Dealer Profile Data'!$AH:$AH,$A15,'AMP Dealer Profile Data'!$AK:$AK,"High") -> 0 | F15: =COUNTIFS('AMP Dealer Profile Data'!$AH:$AH,$A15,'AMP Dealer Profile Data'!$AK:$AK,"Medium") -> 0 | G15: =COUNTIFS('AMP Dealer Profile Data'!$AH:$AH,$A15,'AMP Dealer Profile Data'!$AK:$AK,"Low (candidates found but none loaded cleanly)") -> 0 | H15: =COUNTIFS('AMP Dealer Profile Data'!$AH:$AH,$A15,'AMP Dealer Profile Data'!$AK:$AK,"None (no sitemap found; homepage links yielded no candidates)") -> 0
